Workbook
Name Awareness: References!$M$3:$M$7
Name EaseofExploit: References!$K$3:$K$7
Name EasyofDiscovery: References!$I$3:$I$7
Name FinancialDamage: References!$I$12:$I$16
Name IntrusionDetection: References!$O$3:$O$7
Name LossofAccountability: References!$G$12:$G$15
Name LossofAvailability: References!$E$12:$E$16
Name LossofConfidentiality: References!$A$12:$A$16
Name LossofIntegrity: References!$C$12:$C$17
Name Motive: References!$C$3:$C$6
Name NonCompliance: References!$M$12:$M$15
Name Opportunity: References!$E$3:$E$6
Name PolicyViolation: References!$O$12:$O$16
Name PopulationSize: References!$G$3:$G$8
Name ReputationDamage: References!$K$12:$K$16
Name result: 'Lista de Pruebas'!$A$125:$A$127
Name SkillRequired: References!$A$3:$A$8

Sheet Lista de Pruebas
A1: OWASP: Lista de verificación de la Guía de pruebas v4.2
A2: Pruebas_de_Seguridad_de_aplicaciones_Web
A4: Recopilación de información | B4: Nombre de la prueba | C4: Objetivos | D4: Estado | E4: Notas
A5: WSTG-INFO-01 | B5: Realizar un reconocimiento de motores de búsqueda para detectar fugas de información | C5: - Identificar qué información confidencial de diseño y configuración de la aplicación, sistema u organización está expuesta directamente (en el sitio web de la organización) o indirectamente (a través de servicios de terceros). | D5: Sin Inicar
A6: WSTG-INFO-02 | B6: Huella del Servidor web | C6: - Determinar la versión y el tipo de un servidor web en ejecución para permitir una mayor detección de cualquier vulnerabilidad conocida. | D6: Sin Inicar
A7: WSTG-INFO-03 | B7: Revisar los metarchivos del servidor web para detectar fugas de información | C7: Identificar rutas y funcionalidades ocultas u ofuscadas a través del análisis de archivos de metadatos. - Extraer y mapear otra información que podría conducir a una mejor comprensión de los sistemas en cuestión. | D7: Sin Inicar
A8: WSTG-INFO-04 | B8: Enumerar aplicaciones en el servidor web | C8: - Enumerar las aplicaciones dentro del alcance que existen en un servidor web. | D8: Sin Inicar
A9: WSTG-INFO-05 | B9: Revisar el contenido de la página web para detectar fugas de información | C9: - Revisar los comentarios y metadatos de la página web para encontrar cualquier fuga de información. - Recopilar archivos JavaScript y revisar el código JS para comprender mejor la aplicación y encontrar cualquier fuga de información. - Identificar si existen archivos de mapas de origen u otros archivos de depuración del frontend. | D9: Sin Inicar
A10: WSTG-INFO-06 | B10: Identificar los puntos de entrada de la aplicación | C10: - Identificar posibles puntos de entrada e inyección mediante análisis de solicitudes y respuestas. | D10: Sin Inicar
A11: WSTG-INFO-07 | B11: Mapear rutas de ejecución a través de la aplicación | C11: - Mapear la aplicación de destino y comprender los flujos de trabajo principales. | D11: Sin Inicar
A12: WSTG-INFO-08 | B12: Huella del Web Framework | C12: - Identificar los componentes que utilizan las aplicaciones web. | D12: Sin Inicar
A13: WSTG-INFO-09 | B13: Huella de la Aplicación Web | D13: Sin Inicar
A14: WSTG-INFO-10 | B14: Mapa de Arquitectura de la aplicación | C14: - Generar un mapa de la aplicación en cuestión en base a la investigación realizada. | D14: Sin Inicar
A16: Pruebas de gestión de configuración e implementación | B16: Nombre de la prueba | C16: Objetivos | D16: Estado | E16: Notas
A17: WSTG-CONF-01 | B17: Configuración de la infraestructura de red de prueba | C17: - Revisar las configuraciones de las aplicaciones establecidas en la red y validar que no sean vulnerables. - Validar que los marcos y sistemas utilizados sean seguros y no sean susceptibles a vulnerabilidades conocidas debido a software sin mantenimiento o configuraciones y credenciales predeterminadas. | D17: Sin Inicar
A18: WSTG-CONF-02 | B18: Configuración de la plataforma de la aplicación de prueba | C18: - Asegúrese de que se hayan eliminado los archivos predeterminados y conocidos. - Valide que no queden códigos de depuración ni extensiones en los entornos de producción. - Revise los mecanismos de registro establecidos para la aplicación. | D18: Sin Inicar
A19: WSTG-CONF-03 | B19: Manejo de extensiones de archivo de prueba para información confidencial | C19: - Eliminar extensiones de archivos sensibles o extensiones que puedan contener datos sin procesar (p. ej., scripts, datos sin procesar, credenciales, etc.). - Validar que no existan omisiones del marco del sistema en el conjunto de reglas. | D19: Sin Inicar
A20: WSTG-CONF-04 | B20: Revisar copias de seguridad antiguas y archivos sin referencia para obtener información confidencial | C20: - Busque y analice archivos no referenciados que puedan contener información confidencial. | D20: Sin Inicar
A21: WSTG-CONF-05 | B21: Enumerar las interfaces de administración de aplicaciones e infraestructura | C21: - Identificar interfaces y funcionalidades de administrador ocultas. | D21: Sin Inicar
A22: WSTG-CONF-06 | B22: Probar métodos HTTP | C22: - Enumerar los métodos HTTP admitidos. - Probar la omisión del control de acceso. - Probar las vulnerabilidades de XST. - Probar las técnicas de anulación de métodos HTTP. | D22: Sin Inicar
A23: WSTG-CONF-07 | B23: Prueba de seguridad de transporte estricta HTTP | C23: - Revisar el encabezado HSTS y su validez. | D23: Sin Inicar
A24: WSTG-CONF-08 | B24: Probar la política entre dominios de RIA | C24: - Revisar y validar los archivos de políticas. | D24: Sin Inicar
A25: WSTG-CONF-09 | B25: Permiso de archivo de prueba | C25: - Revise e identifique cualquier permiso de archivo no autorizado. | D25: Sin Inicar
A26: WSTG-CONF-10 | B26: Prueba de toma de control de subdominio | C26: - Enumerar todos los dominios posibles (anteriores y actuales). - Identificar dominios olvidados o mal configurados. | D26: Sin Inicar
A27: WSTG-CONF-11 | B27: Prueba el almacenamiento en la nube | C27: - Evaluar que la configuración del control de acceso para los servicios de almacenamiento esté correctamente establecida. | D27: Sin Inicar
A29: Pruebas de gestión de identidad | B29: Nombre de la prueba | C29: Objetivos | D29: Estado | E29: Notas
A30: WSTG-IDNT-01 | B30: Definiciones de roles de prueba | C30: - Identificar y documentar los roles utilizados por la aplicación. - Intentar cambiar, modificar o acceder a otro rol. - Revisar la granularidad de los roles y las necesidades detrás de los permisos otorgados. | D30: Sin Inicar
A31: WSTG-IDNT-02 | B31: Proceso de registro de usuarios de prueba | C31: - Verificar que los requisitos de identidad para el registro de usuarios estén alineados con los requisitos del negocio y de seguridad. - Validar el proceso de registro. | D31: Sin Inicar
A32: WSTG-IDNT-03 | B32: Proceso de aprovisionamiento de cuentas de prueba | C32: - Verificar qué cuentas pueden aprovisionar otras cuentas y de qué tipo. | D32: Sin Inicar
A33: WSTG-IDNT-04 | B33: Prueba de enumeración de cuentas y cuentas de usuario adivinables | C33: - Revisar los procesos relacionados con la identificación de usuarios (por ejemplo, registro, inicio de sesión, etc.). - Enumerar a los usuarios siempre que sea posible a través del análisis de respuestas. | D33: Sin Inicar
A34: WSTG-IDNT-05 | B34: Prueba de políticas de nombre de usuario débiles o no aplicadas | C34: - Determinar si una estructura de nombre de cuenta consistente hace que la aplicación sea vulnerable a la enumeración de cuentas. - Determinar si los mensajes de error de la aplicación permiten la enumeración de cuentas. | D34: Sin Inicar
A36: Pruebas de autenticación | B36: Nombre de la prueba | C36: Objetivos | D36: Estado | E36: Notas
A37: WSTG-ATHN-01 | B37: Prueba de credenciales transportadas a través de un canal cifrado | C37: - Evaluar si algún caso de uso del sitio web o la aplicación hace que el servidor o el cliente intercambien credenciales sin cifrado. | D37: Sin Inicar
A38: WSTG-ATHN-02 | B38: Prueba de credenciales predeterminadas | C38: Enumerar las aplicaciones en busca de credenciales predeterminadas y validar si aún existen. - Revisar y evaluar las nuevas cuentas de usuario y si se crean con algún valor predeterminado o patrones identificables. | D38: Sin Inicar
A39: WSTG-ATHN-03 | B39: Prueba de mecanismo de bloqueo débil | C39: - Evaluar la capacidad del mecanismo de bloqueo de cuentas para mitigar la adivinación de contraseñas por fuerza bruta.- Evaluar la resistencia del mecanismo de desbloqueo al desbloqueo de cuentas no autorizado. | D39: Sin Inicar
A40: WSTG-ATHN-04 | B40: Prueba para eludir el esquema de autenticación | C40: - Asegúrese de que la autenticación se aplique en todos los servicios que la requieran. | D40: Sin Inicar
A41: WSTG-ATHN-05 | B41: Prueba de contraseñas vulnerables | C41: - Validar que la sesión generada se gestione de forma segura y no ponga en peligro las credenciales del usuario. | D41: Sin Inicar
A42: WSTG-ATHN-06 | B42: Prueba de debilidades de la caché del navegador | C42: - Revisar si la aplicación almacena información confidencial en el lado del cliente. - Revisar si se puede acceder sin autorización. | D42: Sin Inicar
A43: WSTG-ATHN-07 | B43: Prueba de políticas de contraseñas débiles | C43: - Determinar la resistencia de la aplicación contra la adivinación de contraseñas por fuerza bruta utilizando diccionarios de contraseñas disponibles evaluando los requisitos de longitud, complejidad, reutilización y antigüedad de las contraseñas. | D43: Sin Inicar
A44: WSTG-ATHN-08 | B44: Prueba de respuesta a preguntas de seguridad débiles | C44: - Determinar la complejidad y qué tan directas son las preguntas. - Evaluar las posibles respuestas de los usuarios y las capacidades de fuerza bruta. | D44: Sin Inicar
...

Sheet  Resumen de hallazgos
A1: No. | B1: Nombre de la vulnerabilidad | C1: OTG | D1: Host/ruta afectado | E1: Impacto | F1: Probabilidad | G1: Riesgo | H1: Observación/Implicación | I1: Recomendación | J1: Prueba de evidencia
A2: 1 | B2: Inyección SQL | C2: WSTG-INPV-05 | D2: www.ejemplo.com/noticias.php (id,página) | E2: Alto | F2: Moderado | G2: Alto | J2: xxx-1

Sheet  Calculadora de evaluación de r
A1: Calculadora de evaluación de riesgos de OWASP Calculadora de evaluación de riesgos
A3: Factores de probabilidad | F3: Factores de impacto
A4: Factores del agente de amenaza | F4: Factores de impacto técnico
A5: Habilidades requeridas | B5: Algunas habilidades técnicas [3] | E5: =VLOOKUP(B5, References!A2:B8,2,0) -> 3 | F5: Pérdida de confidencialidad | G5: Datos mínimos no sensibles divulgados [2] | H5: =VLOOKUP(G5, References!A$11:B$16,2,0) -> 2
A6: Motivo | B6: Posible recompensa [4] | E6: =VLOOKUP(B6, References!C2:D6,2,0) -> 4 | F6: Pérdida de integridad | G6: Todos los datos están totalmente corruptos [9] | H6: =VLOOKUP(G6, References!C$11:D$17,2,0) -> 9
A7: Oportunidad | B7: Se requiere acceso total o recursos costosos [0] | E7: =VLOOKUP(B7, References!E2:F6,2,0) -> 0 | F7: Pérdida de disponibilidad | G7: Servicios secundarios mínimos interrumpidos [1] | H7: =VLOOKUP(G7, References!E$11:F$16,2,0) -> 1
A8: Tamaño de la población | B8: Administradores de sistemas [2] | E8: =VLOOKUP(B8, References!G3:H8,2,0) -> 2 | F8: Pérdida de responsabilidad | G8: No aplicable [0] | H8: =VLOOKUP(G8, References!G$11:H$16,2,0) -> 0
A10: Factores de vulnerabilidad | F10: Factores de impacto empresarial
A11: Fácil de descubrir | B11: Prácticamente imposible [1] | E11: =VLOOKUP(B11, References!I2:J7,2,0) -> 1 | F11: Daños financieros | G11: Efecto menor en el beneficio anual [3] | H11: =VLOOKUP(G11, References!I$11:J$16,2,0) -> 3
A12: Facilidad de explotación | B12: Fácil [5] | E12: =VLOOKUP(B12, References!K$2:L$7,2,0) -> 5 | F12: Daño a la reputación | G12: Pérdida de cuentas importantes [4] | H12: =VLOOKUP(G12, References!K$11:L$16,2,0) -> 4
A13: Conciencia | B13: Oculto [4] | E13: =VLOOKUP(B13, References!M$2:N$7,2,0) -> 4 | F13: Incumplimiento | G13: Violación clara [5] | H13: =VLOOKUP(G13, References!M$11:O$16,2,0) -> 5
A14: Detección de intrusiones | B14: Registrado y revisado [3] | E14: =VLOOKUP(B14, References!O$2:P$7,2,0) -> 3 | F14: Violación de la privacidad | G14: Un individuo [3] | H14: =VLOOKUP(G14, References!O$11:P$16,2,0) -> 3
A16: Puntuación de verosimilitud: | B16: =IFERROR(AVERAGE(E5:E8,E11:E14),"All factors require a selection.") -> 2.75 | F16: Puntuación de impacto: | G16: =IFERROR(AVERAGE(H5:H8,H11:H14),"All factors require a selection.") -> 3.375
B20: Gravedad general del riesgo: | E20: =IFERROR(IF(AND($B$16<3,$G$16<3),"Note",IF(OR(AND($B$16<3,$G$16>=3,$G$16<6),AND($B$16>=3,$B$16<6,$G$16<3)),"Low",IF(OR(AND($B16<3,$G16>=6),AND($B16>=3,$B16<6,$G16>=3,$G16<6),AND($B16>=6,$G16<3)),"MODERATE",IF(OR(AND($B16>=6,$B16>=3,$G16<6),AND($B16>=3,$B16<6,$G16>6)),"High","Critical")))),"Note") -> Low
B22: Impacto
A23: Probabilidad | B23: =IF($G16<3,"->Low<-","Low") -> Low | C23: =IF(AND($G16>=3,$G16<6),"->Moderate<-","Moderate") -> ->Moderate<- | D23: =IF($G16>=6,"->High<-","High") -> High
A24: =IF($B16<3,"->Low<-","Low") -> ->Low<- | B24: =IF(AND($B$16<3,$G$16<3),"->Note<-","Note") -> Note | C24: =IF(AND($B$16<3,$G$16>=3,$G$16<6),"->Low<-","Low") -> ->Low<- | D24: =IF(AND($B16<3,$G16>=6),"->Moderate<-","Moderate") -> Moderate
A25: =IF(AND($B16>=3,$B16<6),"->Moderate<-","Moderate") -> Moderate | B25: =IF(AND($B$16>=3,$B$16<6,$G$16<3),"->Low<-","Low") -> Low | C25: =IF(AND($B16>=3,$B16<6,$G16>=3,$G16<6),"->Moderate<-","Moderate") -> Moderate | D25: =IF(AND($B16>=3,$B16<6,$G16>6),"->High<-","High") -> High
A26: =IF($B16>=6,"->High<-","High") -> High | B26: =IF(AND($B16>=6,$G16<3),"->Moderate<-","Moderate") -> Moderate | C26: =IF(AND($B16>=6,$B16>=3,$G16<6),"->High<-","High") -> High | D26: =IF(AND($B$16>=6,$G$16>=6),"->Critical<-","Critical") -> Critical

Sheet References
A1: Habilidades requeridas | C1: Motivo | E1: Oportunidad | G1: Tamaño de la población | I1: Fácil de descubrir | K1: Facilidad de explotación | M1: Conciencia | O1: Detección de intrusiones
A2: Seleccione una opción | C2: Seleccione una opción | E2: Seleccione una opción | G2: Seleccione una opción | I2: Seleccione una opción | K2: Seleccione una opción | M2: Seleccione una opción | O2: Seleccione una opción
A3: No aplicable [0] | B3: 0 | C3: No aplicable [0] | D3: 0 | E3: Se requiere acceso total o recursos costosos [0] | F3: 0 | G3: No aplicable [0] | H3: 0 | I3: No aplicable [0] | J3: 0 | K3: No aplicable [0] | L3: 0 | M3: No aplicable [0] | N3: 0 | O3: No aplicable [0] | P3: 0
A4: Sin habilidades técnicas [1] | B4: 1 | C4: Recompensa baja o nula [1] | D4: 1 | E4: Se requieren accesos o recursos especiales [4] | F4: 4 | G4: Administradores de sistemas [2] | H4: 2 | I4: Prácticamente imposible [1] | J4: 1 | K4: Teórico [1] | L4: 1 | M4: Desconocido [1] | N4: 1 | O4: Detección activa en la aplicación [1] | P4: 1
A5: Algunas habilidades técnicas [3] | B5: 3 | C5: Posible recompensa [4] | D5: 4 | E5: Se requiere algún acceso o recursos [7] | F5: 7 | G5: Usuarios de la intranet [4] | H5: 4 | I5: Difícil [3] | J5: 3 | K5: Difícil [3] | L5: 3 | M5: Oculto [4] | N5: 4 | O5: Registrado y revisado [3] | P5: 3
A6: Usuario avanzado de computadora [5] | B6: 5 | C6: Alta recompensa [9] | D6: 9 | E6: No se requiere acceso ni recursos [9] | F6: 9 | G6: Socios [5] | H6: 5 | I6: Fácil [7] | J6: 7 | K6: Fácil [5] | L6: 5 | M6: Obvio [6] | N6: 6 | O6: Registrado sin revisión [8] | P6: 8
A7: Habilidades de red y programación [6] | B7: 6 | G7: Usuarios autenticados [6] | H7: 6 | I7: Herramientas automatizadas disponibles [9] | J7: 9 | K7: Herramientas automatizadas disponibles [9] | L7: 9 | M7: Conocimiento público [9] | N7: 9 | O7: No registrado [9] | P7: 9
A8: Habilidades de penetración de seguridad [9] | B8: 9 | G8: Usuarios anónimos de Internet [9] | H8: 9
A10: Pérdida de confidencialidad | C10: Pérdida de integridad | E10: Pérdida de disponibilidad | G10: Pérdida de responsabilidad | I10: Daños financieros | K10: Daño a la reputación | M10: Incumplimiento | O10: Violación de la privacidad
A11: Seleccione una opción | C11: Seleccione una opción | E11: Seleccione una opción | G11: Seleccione una opción | I11: Seleccione una opción | K11: Seleccione una opción | M11: Seleccione una opción | O11: Seleccione una opción
A12: No aplicable [0] | B12: 0 | C12: No aplicable [0] | D12: 0 | E12: No aplicable [0] | F12: 0 | G12: No aplicable [0] | H12: 0 | I12: No aplicable [0] | J12: 0 | K12: No aplicable [0] | L12: 0 | M12: No aplicable [0] | N12: 0 | O12: No aplicable [0] | P12: 0
A13: Datos mínimos no sensibles divulgados [2] | B13: 2 | C13: Datos mínimos ligeramente corruptos [1] | D13: 1 | E13: Servicios secundarios mínimos interrumpidos [1] | F13: 1 | G13: Ataque totalmente rastreable hasta el individuo [1] | H13: 1 | I13: El daño cuesta menos que arreglar el problema [1] | J13: 1 | K13: Daños mínimos [1] | L13: 1 | M13: Infracción menor [2] | N13: 2 | O13: Un individuo [3] | P13: 3
A14: Se divulgaron numerosos datos no sensibles [6] | B14: 6 | C14: Datos mínimos gravemente corruptos [3] | D14: 3 | E14: Servicios primarios mínimos interrumpidos [5] | F14: 5 | G14: Ataque posiblemente atribuible a un individuo [7] | H14: 7 | I14: Efecto menor en el beneficio anual [3] | J14: 3 | K14: Pérdida de cuentas importantes [4] | L14: 4 | M14: Violación clara [5] | N14: 5 | O14: Cientos de personas [5] | P14: 5
A15: Se revelaron amplios datos críticos [7] | B15: 7 | C15: Amplios datos ligeramente corruptos [5] | D15: 5 | E15: Se interrumpieron amplios servicios primarios [7] | F15: 7 | G15: Ataque completamente anónimo [9] | H15: 9 | I15: Efecto significativo en el beneficio anual [7] | J15: 7 | K15: Pérdida de prestigio [5] | L15: 5 | M15: Violación de alto perfil [7] | N15: 7 | O15: Miles de personas [7] | P15: 7
A16: Todos los datos divulgados [9] | B16: 9 | C16: Amplios datos gravemente corruptos [7] | D16: 7 | E16: Todos los servicios se perdieron por completo [9] | F16: 9 | I16: Quiebra [9] | J16: 9 | K16: Daño a la marca [9] | L16: 9 | O16: Millones de personas [9] | P16: 9
C17: Todos los datos están totalmente corruptos [9] | D17: 9
